Traceback (most recent call last):
  File "C:\Users\roman\anaconda3\envs\jupyterbook\lib\site-packages\jupyter_cache\executors\utils.py", line 58, in single_nb_execution
    executenb(
  File "C:\Users\roman\anaconda3\envs\jupyterbook\lib\site-packages\nbclient\client.py", line 1305, in execute
    return NotebookClient(nb=nb, resources=resources, km=km, **kwargs).execute()
  File "C:\Users\roman\anaconda3\envs\jupyterbook\lib\site-packages\jupyter_core\utils\__init__.py", line 166, in wrapped
    return loop.run_until_complete(inner)
  File "C:\Users\roman\anaconda3\envs\jupyterbook\lib\asyncio\base_events.py", line 647, in run_until_complete
    return future.result()
  File "C:\Users\roman\anaconda3\envs\jupyterbook\lib\site-packages\nbclient\client.py", line 705, in async_execute
    await self.async_execute_cell(
  File "C:\Users\roman\anaconda3\envs\jupyterbook\lib\site-packages\nbclient\client.py", line 1058, in async_execute_cell
    await self._check_raise_for_error(cell, cell_index, exec_reply)
  File "C:\Users\roman\anaconda3\envs\jupyterbook\lib\site-packages\nbclient\client.py", line 914, in _check_raise_for_error
    raise CellExecutionError.from_cell_and_msg(cell, exec_reply_content)
nbclient.exceptions.CellExecutionError: An error occurred while executing the following cell:
------------------
data_url = 'https://raw.githubusercontent.com/datasets/gdp/master/data/gdp.csv'

df = pd.read_csv(data_url)

denmark_df = df[df['Country Name'] == 'Denmark']
netherlands_df = df[df['Country Name'] == 'Netherlands']

years = [2019, 2020, 2021, 2022]
denmark_gdp_values = [346500000000.06, 355220000000.01, 398300000000.09]
netherlands_gdp_values = [910190000000.04, 909790000000.03, 1012850000000.01]

for year, denmark_gdp, netherlands_gdp in zip(years, denmark_gdp_values, netherlands_gdp_values):
    denmark_df = denmark_df.append({'Country Name': 'Denmark', 'Year': year, 'Value': denmark_gdp}, ignore_index=True)
    netherlands_df = netherlands_df.append({'Country Name': 'Netherlands', 'Year': year, 'Value': netherlands_gdp}, ignore_index=True)


denmark_df = denmark_df[denmark_df['Year'] >= 2004]
netherlands_df = netherlands_df[netherlands_df['Year'] >= 2004]
------------------


[1;31m---------------------------------------------------------------------------[0m
[1;31mAttributeError[0m                            Traceback (most recent call last)
[1;32m~\AppData\Local\Temp\ipykernel_35228\1271564147.py[0m in [0;36m?[1;34m()[0m
[0;32m     12[0m [0mdata_url[0m [1;33m=[0m [1;34m'https://raw.githubusercontent.com/datasets/gdp/master/data/gdp.csv'[0m[1;33m[0m[1;33m[0m[0m
[1;32m---> 13[1;33m [1;33m[0m[0m
[0m[0;32m     14[0m [0mdf[0m [1;33m=[0m [0mpd[0m[1;33m.[0m[0mread_csv[0m[1;33m([0m[0mdata_url[0m[1;33m)[0m[1;33m[0m[1;33m[0m[0m
[0;32m     15[0m [1;33m[0m[0m
[0;32m     16[0m [0mdenmark_df[0m [1;33m=[0m [0mdf[0m[1;33m[[0m[0mdf[0m[1;33m[[0m[1;34m'Country Name'[0m[1;33m][0m [1;33m==[0m [1;34m'Denmark'[0m[1;33m][0m[1;33m[0m[1;33m[0m[0m

[1;32m~\anaconda3\envs\jupyterbook\lib\site-packages\pandas\core\generic.py[0m in [0;36m?[1;34m(self, name)[0m
[0;32m   5985[0m             [1;32mand[0m [0mname[0m [1;32mnot[0m [1;32min[0m [0mself[0m[1;33m.[0m[0m_accessors[0m[1;33m[0m[1;33m[0m[0m
[0;32m   5986[0m             [1;32mand[0m [0mself[0m[1;33m.[0m[0m_info_axis[0m[1;33m.[0m[0m_can_hold_identifiers_and_holds_name[0m[1;33m([0m[0mname[0m[1;33m)[0m[1;33m[0m[1;33m[0m[0m
[0;32m   5987[0m         ):
[0;32m   5988[0m             [1;32mreturn[0m [0mself[0m[1;33m[[0m[0mname[0m[1;33m][0m[1;33m[0m[1;33m[0m[0m
[1;32m-> 5989[1;33m         [1;32mreturn[0m [0mobject[0m[1;33m.[0m[0m__getattribute__[0m[1;33m([0m[0mself[0m[1;33m,[0m [0mname[0m[1;33m)[0m[1;33m[0m[1;33m[0m[0m
[0m
[1;31mAttributeError[0m: 'DataFrame' object has no attribute 'append'

